Workbook

Sheet 배당편집
A1: Ticker | B1: 연도 | C1: 월 | D1: 임시 | E1: Ex-Dividend Date | F1: Dividend | G1: Payment Date | H1: Yield | I1: Increased Rate | J1: Div Change | K1: - | L1: 연도2 | M1: 임시2 | N1: 현재가치 배당금 | O1: 배당수익률 | P1: - | Q1: 연평균배당 | R1: 5년산술평균 | S1: 배당성장률 | T1: 5년기하평균 | W1: 배당금 변화 | X1: 배당금 변화율
A2: JNJ | B2: =YEAR(E2) -> 2022 | C2: =MONTH(E2) -> 11 | D2: =A2&B2&C2 -> JNJ202211 | E2: 44886 | F2: 1.13 | G2: 44901 | H2: 0.0258 | I2: 0 | J2: 0 | K2: =IF(YEAR(E2)=YEAR(E3),YEAR(E2),0) -> 2022 | L2: =IF(K2=0,K1,0) -> 0 | M2: =A2&L2 -> JNJ0 | N2: =F2 -> 1.13 | O2: =H2 -> 0.0258 | P2: =IF(S2>0,SUM(O2:O5)/4,0) -> 0 | Q2: 0 | R2: 배당수익률 | S2: =IF(A2=A3,(N2-N3)/N3,0) -> 0 | T2: 배당성장률 | U2: 요구수익률 | W2: =IF(A2=A3,N2-N3,0) -> 0 | X2: =IF(A2=A3,(N2-N3)/N3,0) -> 0
A3: JNJ | B3: =YEAR(E3) -> 2022 | C3: =MONTH(E3) -> 8 | D3: =A3&B3&C3 -> JNJ20228 | E3: 44795 | F3: 1.13 | G3: 44810 | H3: 0.0267 | I3: 0 | J3: 0 | K3: =IF(YEAR(E3)=YEAR(E4),YEAR(E3),0) -> 2022 | L3: =IF(K3=0,K2,0) -> 0 | M3: =A3&L3 -> JNJ0 | N3: =F3 -> 1.13 | O3: =H3 -> 0.0267 | P3: =IF(S3>0,SUM(O3:O6)/4,0) -> 0 | Q3: 0 | R3: X | S3: =IF(A3=A4,(N3-N4)/N4,0) -> 0 | T3: gi | U3: ki | V3: 고든계수 | W3: =IF(A3=A4,N3-N4,0) -> 0 | X3: =IF(A3=A4,(N3-N4)/N4,0) -> 0
A4: JNJ | B4: =YEAR(E4) -> 2022 | C4: =MONTH(E4) -> 5 | D4: =A4&B4&C4 -> JNJ20225 | E4: 44704 | F4: 1.13 | G4: 44719 | H4: 0.0255 | I4: 0.066037736 | J4: 0.07 | K4: =IF(YEAR(E4)=YEAR(E5),YEAR(E4),0) -> 2022 | L4: =IF(K4=0,K3,0) -> 0 | M4: =A4&L4 -> JNJ0 | N4: =F4 -> 1.13 | O4: =H4 -> 0.0255 | P4: =IF(S4>0,SUM(O4:O7)/4,0) -> 0.02515 | Q4: 0 | S4: =IF(A4=A5,(N4-N5)/N5,0) -> 0.066037736 | W4: =IF(A4=A5,N4-N5,0) -> 0.07 | X4: =IF(A4=A5,(N4-N5)/N5,0) -> 0.066037736
A5: JNJ | B5: =YEAR(E5) -> 2022 | C5: =MONTH(E5) -> 2 | D5: =A5&B5&C5 -> JNJ20222 | E5: 44610 | F5: 1.06 | G5: 44628 | H5: 0.0255 | I5: 0 | J5: 0 | K5: =IF(YEAR(E5)=YEAR(E6),YEAR(E5),0) -> 0 | L5: =IF(K5=0,K4,0) -> 2022 | M5: =A5&L5 -> JNJ2022 | N5: =F5 -> 1.06 | O5: =H5 -> 0.0255 | P5: =IF(S5>0,SUM(O5:O8)/4,0) -> 0 | Q5: =IF(K5=0,IF(A2=A5,AVERAGE(O2:O5),"x"),0) -> 0.025875 | R5: =IF(L5>2005,AVERAGE(O2:O21),0) -> 0.026355 | S5: =IF(A5=A6,(N5-N6)/N6,0) -> 0 | T5: =IF(L5>2005,(((N5-N25)/N25)+1)^(1/5)-1,0) -> 0.057896489 | U5: =IF(T5>0,R5+T5,0) -> 0.084251489 | V5: =IF(U5>0,(1+T5)*(1-((1+T5)/(1+U5))^5)/(U5-T5),0) -> 4.646997 | W5: =IF(A5=A6,N5-N6,0) -> 0 | X5: =IF(A5=A6,(N5-N6)/N6,0) -> 0
A6: JNJ | B6: =YEAR(E6) -> 2021 | C6: =MONTH(E6) -> 11 | D6: =A6&B6&C6 -> JNJ202111 | E6: 44522 | F6: 1.06 | G6: 44537 | H6: 0.026 | I6: 0 | J6: 0 | K6: =IF(YEAR(E6)=YEAR(E7),YEAR(E6),0) -> 2021 | L6: =IF(K6=0,K5,0) -> 0 | M6: =A6&L6 -> JNJ0 | N6: =F6 -> 1.06 | O6: =H6 -> 0.026 | P6: =IF(S6>0,SUM(O6:O9)/4,0) -> 0 | Q6: =IF(K6=0,IF(A3=A6,AVERAGE(O3:O6),"x"),0) -> 0 | R6: =IF(L6>2005,AVERAGE(O3:O22),0) -> 0 | S6: =IF(A6=A7,(N6-N7)/N7,0) -> 0 | T6: =IF(L6>2005,(((N6-N26)/N26)+1)^(1/5)-1,0) -> 0 | U6: =IF(T6>0,R6+T6,0) -> 0 | V6: =IF(U6>0,(1+T6)*(1-((1+T6)/(1+U6))^5)/(U6-T6),0) -> 0 | W6: =IF(A6=A7,N6-N7,0) -> 0 | X6: =IF(A6=A7,(N6-N7)/N7,0) -> 0
A7: JNJ | B7: =YEAR(E7) -> 2021 | C7: =MONTH(E7) -> 8 | D7: =A7&B7&C7 -> JNJ20218 | E7: 44431 | F7: 1.06 | G7: 44446 | H7: 0.0236 | I7: 0 | J7: 0 | K7: =IF(YEAR(E7)=YEAR(E8),YEAR(E7),0) -> 2021 | L7: =IF(K7=0,K6,0) -> 0 | M7: =A7&L7 -> JNJ0 | N7: =F7 -> 1.06 | O7: =H7 -> 0.0236 | P7: =IF(S7>0,SUM(O7:O10)/4,0) -> 0 | Q7: =IF(K7=0,IF(A4=A7,AVERAGE(O4:O7),"x"),0) -> 0 | R7: =IF(L7>2005,AVERAGE(O4:O23),0) -> 0 | S7: =IF(A7=A8,(N7-N8)/N8,0) -> 0 | T7: =IF(L7>2005,(((N7-N27)/N27)+1)^(1/5)-1,0) -> 0 | U7: =IF(T7>0,R7+T7,0) -> 0 | V7: =IF(U7>0,(1+T7)*(1-((1+T7)/(1+U7))^5)/(U7-T7),0) -> 0 | W7: =IF(A7=A8,N7-N8,0) -> 0 | X7: =IF(A7=A8,(N7-N8)/N8,0) -> 0
A8: JNJ | B8: =YEAR(E8) -> 2021 | C8: =MONTH(E8) -> 5 | D8: =A8&B8&C8 -> JNJ20215 | E8: 44340 | F8: 1.06 | G8: 44355 | H8: 0.0248 | I8: 0.04950495 | J8: 0.05 | K8: =IF(YEAR(E8)=YEAR(E9),YEAR(E8),0) -> 2021 | L8: =IF(K8=0,K7,0) -> 0 | M8: =A8&L8 -> JNJ0 | N8: =F8 -> 1.06 | O8: =H8 -> 0.0248 | P8: =IF(S8>0,SUM(O8:O11)/4,0) -> 0.0259 | Q8: =IF(K8=0,IF(A5=A8,AVERAGE(O5:O8),"x"),0) -> 0 | R8: =IF(L8>2005,AVERAGE(O5:O24),0) -> 0 | S8: =IF(A8=A9,(N8-N9)/N9,0) -> 0.04950495 | T8: =IF(L8>2005,(((N8-N28)/N28)+1)^(1/5)-1,0) -> 0 | U8: =IF(T8>0,R8+T8,0) -> 0 | V8: =IF(U8>0,(1+T8)*(1-((1+T8)/(1+U8))^5)/(U8-T8),0) -> 0 | W8: =IF(A8=A9,N8-N9,0) -> 0.05 | X8: =IF(A8=A9,(N8-N9)/N9,0) -> 0.04950495
A9: JNJ | B9: =YEAR(E9) -> 2021 | C9: =MONTH(E9) -> 2 | D9: =A9&B9&C9 -> JNJ20212 | E9: 44249 | F9: 1.01 | G9: 44264 | H9: 0.0248 | I9: 0 | J9: 0 | K9: =IF(YEAR(E9)=YEAR(E10),YEAR(E9),0) -> 0 | L9: =IF(K9=0,K8,0) -> 2021 | M9: =A9&L9 -> JNJ2021 | N9: =F9 -> 1.01 | O9: =H9 -> 0.0248 | P9: =IF(S9>0,SUM(O9:O12)/4,0) -> 0 | Q9: =IF(K9=0,IF(A6=A9,AVERAGE(O6:O9),"x"),0) -> 0.0248 | R9: =IF(L9>2005,AVERAGE(O6:O25),0) -> 0.026295 | S9: =IF(A9=A10,(N9-N10)/N10,0) -> 0 | T9: =IF(L9>2005,(((N9-N29)/N29)+1)^(1/5)-1,0) -> 0.061333865 | U9: =IF(T9>0,R9+T9,0) -> 0.087628865 | V9: =IF(U9>0,(1+T9)*(1-((1+T9)/(1+U9))^5)/(U9-T9),0) -> 4.6488334 | W9: =IF(A9=A10,N9-N10,0) -> 0 | X9: =IF(A9=A10,(N9-N10)/N10,0) -> 0
A10: JNJ | B10: =YEAR(E10) -> 2020 | C10: =MONTH(E10) -> 11 | D10: =A10&B10&C10 -> JNJ202011 | E10: 44158 | F10: 1.01 | G10: 44173 | H10: 0.0276 | I10: 0 | J10: 0 | K10: =IF(YEAR(E10)=YEAR(E11),YEAR(E10),0) -> 2020 | L10: =IF(K10=0,K9,0) -> 0 | M10: =A10&L10 -> JNJ0 | N10: =F10 -> 1.01 | O10: =H10 -> 0.0276 | P10: =IF(S10>0,SUM(O10:O13)/4,0) -> 0 | Q10: =IF(K10=0,IF(A7=A10,AVERAGE(O7:O10),"x"),0) -> 0 | R10: =IF(L10>2005,AVERAGE(O7:O26),0) -> 0 | S10: =IF(A10=A11,(N10-N11)/N11,0) -> 0 | T10: =IF(L10>2005,(((N10-N30)/N30)+1)^(1/5)-1,0) -> 0 | U10: =IF(T10>0,R10+T10,0) -> 0 | V10: =IF(U10>0,(1+T10)*(1-((1+T10)/(1+U10))^5)/(U10-T10),0) -> 0 | W10: =IF(A10=A11,N10-N11,0) -> 0 | X10: =IF(A10=A11,(N10-N11)/N11,0) -> 0
A11: JNJ | B11: =YEAR(E11) -> 2020 | C11: =MONTH(E11) -> 8 | D11: =A11&B11&C11 -> JNJ20208 | E11: 44067 | F11: 1.01 | G11: 44082 | H11: 0.0264 | I11: 0 | J11: 0 | K11: =IF(YEAR(E11)=YEAR(E12),YEAR(E11),0) -> 2020 | L11: =IF(K11=0,K10,0) -> 0 | M11: =A11&L11 -> JNJ0 | N11: =F11 -> 1.01 | O11: =H11 -> 0.0264 | P11: =IF(S11>0,SUM(O11:O14)/4,0) -> 0 | Q11: =IF(K11=0,IF(A8=A11,AVERAGE(O8:O11),"x"),0) -> 0 | R11: =IF(L11>2005,AVERAGE(O8:O27),0) -> 0 | S11: =IF(A11=A12,(N11-N12)/N12,0) -> 0 | T11: =IF(L11>2005,(((N11-N31)/N31)+1)^(1/5)-1,0) -> 0 | U11: =IF(T11>0,R11+T11,0) -> 0 | V11: =IF(U11>0,(1+T11)*(1-((1+T11)/(1+U11))^5)/(U11-T11),0) -> 0 | W11: =IF(A11=A12,N11-N12,0) -> 0 | X11: =IF(A11=A12,(N11-N12)/N12,0) -> 0
A12: JNJ | B12: =YEAR(E12) -> 2020 | C12: =MONTH(E12) -> 5 | D12: =A12&B12&C12 -> JNJ20205 | E12: 43973 | F12: 1.01 | G12: 43991 | H12: 0.0275 | I12: 0.063157895 | J12: 0.06 | K12: =IF(YEAR(E12)=YEAR(E13),YEAR(E12),0) -> 2020 | L12: =IF(K12=0,K11,0) -> 0 | M12: =A12&L12 -> JNJ0 | N12: =F12 -> 1.01 | O12: =H12 -> 0.0275 | P12: =IF(S12>0,SUM(O12:O15)/4,0) -> 0.027525 | Q12: =IF(K12=0,IF(A9=A12,AVERAGE(O9:O12),"x"),0) -> 0 | R12: =IF(L12>2005,AVERAGE(O9:O28),0) -> 0 | S12: =IF(A12=A13,(N12-N13)/N13,0) -> 0.063157895 | T12: =IF(L12>2005,(((N12-N32)/N32)+1)^(1/5)-1,0) -> 0 | U12: =IF(T12>0,R12+T12,0) -> 0 | V12: =IF(U12>0,(1+T12)*(1-((1+T12)/(1+U12))^5)/(U12-T12),0) -> 0 | W12: =IF(A12=A13,N12-N13,0) -> 0.06 | X12: =IF(A12=A13,(N12-N13)/N13,0) -> 0.063157895
A13: JNJ | B13: =YEAR(E13) -> 2020 | C13: =MONTH(E13) -> 2 | D13: =A13&B13&C13 -> JNJ20202 | E13: 43885 | F13: 0.95 | G13: 43900 | H13: 0.0253 | I13: 0 | J13: 0 | K13: =IF(YEAR(E13)=YEAR(E14),YEAR(E13),0) -> 0 | L13: =IF(K13=0,K12,0) -> 2020 | M13: =A13&L13 -> JNJ2020 | N13: =F13 -> 0.95 | O13: =H13 -> 0.0253 | P13: =IF(S13>0,SUM(O13:O16)/4,0) -> 0 | Q13: =IF(K13=0,IF(A10=A13,AVERAGE(O10:O13),"x"),0) -> 0.0267 | R13: =IF(L13>2005,AVERAGE(O10:O29),0) -> 0.026895 | S13: =IF(A13=A14,(N13-N14)/N14,0) -> 0 | T13: =IF(L13>2005,(((N13-N33)/N33)+1)^(1/5)-1,0) -> 0.062980048 | U13: =IF(T13>0,R13+T13,0) -> 0.089875048 | V13: =IF(U13>0,(1+T13)*(1-((1+T13)/(1+U13))^5)/(U13-T13),0) -> 4.6417989 | W13: =IF(A13=A14,N13-N14,0) -> 0 | X13: =IF(A13=A14,(N13-N14)/N14,0) -> 0
A14: JNJ | B14: =YEAR(E14) -> 2019 | C14: =MONTH(E14) -> 11 | D14: =A14&B14&C14 -> JNJ201911 | E14: 43794 | F14: 0.95 | G14: 43809 | H14: 0.0275 | I14: 0 | J14: 0 | K14: =IF(YEAR(E14)=YEAR(E15),YEAR(E14),0) -> 2019 | L14: =IF(K14=0,K13,0) -> 0 | M14: =A14&L14 -> JNJ0 | N14: =F14 -> 0.95 | O14: =H14 -> 0.0275 | P14: =IF(S14>0,SUM(O14:O17)/4,0) -> 0 | Q14: =IF(K14=0,IF(A11=A14,AVERAGE(O11:O14),"x"),0) -> 0 | R14: =IF(L14>2005,AVERAGE(O11:O30),0) -> 0 | S14: =IF(A14=A15,(N14-N15)/N15,0) -> 0 | T14: =IF(L14>2005,(((N14-N34)/N34)+1)^(1/5)-1,0) -> 0 | U14: =IF(T14>0,R14+T14,0) -> 0 | V14: =IF(U14>0,(1+T14)*(1-((1+T14)/(1+U14))^5)/(U14-T14),0) -> 0 | W14: =IF(A14=A15,N14-N15,0) -> 0 | X14: =IF(A14=A15,(N14-N15)/N15,0) -> 0
A15: JNJ | B15: =YEAR(E15) -> 2019 | C15: =MONTH(E15) -> 8 | D15: =A15&B15&C15 -> JNJ20198 | E15: 43703 | F15: 0.95 | G15: 43718 | H15: 0.0298 | I15: 0 | J15: 0 | K15: =IF(YEAR(E15)=YEAR(E16),YEAR(E15),0) -> 2019 | L15: =IF(K15=0,K14,0) -> 0 | M15: =A15&L15 -> JNJ0 | N15: =F15 -> 0.95 | O15: =H15 -> 0.0298 | P15: =IF(S15>0,SUM(O15:O18)/4,0) -> 0 | Q15: =IF(K15=0,IF(A12=A15,AVERAGE(O12:O15),"x"),0) -> 0 | R15: =IF(L15>2005,AVERAGE(O12:O31),0) -> 0 | S15: =IF(A15=A16,(N15-N16)/N16,0) -> 0 | T15: =IF(L15>2005,(((N15-N35)/N35)+1)^(1/5)-1,0) -> 0 | U15: =IF(T15>0,R15+T15,0) -> 0 | V15: =IF(U15>0,(1+T15)*(1-((1+T15)/(1+U15))^5)/(U15-T15),0) -> 0 | W15: =IF(A15=A16,N15-N16,0) -> 0 | X15: =IF(A15=A16,(N15-N16)/N16,0) -> 0
A16: JNJ | B16: =YEAR(E16) -> 2019 | C16: =MONTH(E16) -> 5 | D16: =A16&B16&C16 -> JNJ20195 | E16: 43609 | F16: 0.95 | G16: 43627 | H16: 0.0272 | I16: 0.055555556 | J16: 0.05 | K16: =IF(YEAR(E16)=YEAR(E17),YEAR(E16),0) -> 2019 | L16: =IF(K16=0,K15,0) -> 0 | M16: =A16&L16 -> JNJ0 | N16: =F16 -> 0.95 | O16: =H16 -> 0.0272 | P16: =IF(S16>0,SUM(O16:O19)/4,0) -> 0.02635 | Q16: =IF(K16=0,IF(A13=A16,AVERAGE(O13:O16),"x"),0) -> 0 | R16: =IF(L16>2005,AVERAGE(O13:O32),0) -> 0 | S16: =IF(A16=A17,(N16-N17)/N17,0) -> 0.055555556 | T16: =IF(L16>2005,(((N16-N36)/N36)+1)^(1/5)-1,0) -> 0 | U16: =IF(T16>0,R16+T16,0) -> 0 | V16: =IF(U16>0,(1+T16)*(1-((1+T16)/(1+U16))^5)/(U16-T16),0) -> 0 | W16: =IF(A16=A17,N16-N17,0) -> 0.05 | X16: =IF(A16=A17,(N16-N17)/N17,0) -> 0.055555556
... A72: JNJ | B72: =YEAR(E72) -> 2005 | C72: =MONTH(E72) -> 5 | D72: =A72&B72&C72 -> JNJ20055 | E72: 38485 | F72: 0.33 | G72: 38510 | H72: 0.0175 | I72: 0.15789474 | J72: 0.045 | K72: =IF(YEAR(E72)=YEAR(E73),YEAR(E72),0) -> 2005 | L72: =IF(K72=0,K71,0) -> 0 | M72: =A72&L72 -> JNJ0 | N72: =F72 -> 0.33 | O72: =H72 -> 0.0175 | P72: =IF(S72>0,SUM(O72:O75)/4,0) -> 0.017875 | Q72: =IF(K72=0,IF(A69=A72,AVERAGE(O69:O72),"x"),0) -> 0 | R72: =IF(L72>2005,AVERAGE(O69:O88),0) -> 0 | S72: =IF(A72=A73,(N72-N73)/N73,0) -> 0.15789474 | T72: =IF(L72>2005,(((N72-N92)/N92)+1)^(1/5)-1,0) -> 0 | U72: =IF(T72>0,R72+T72,0) -> 0 | V72: =IF(U72>0,(1+T72)*(1-((1+T72)/(1+U72))^5)/(U72-T72),0) -> 0 | W72: =IF(A72=A73,N72-N73,0) -> 0.045 | X72: =IF(A72=A73,(N72-N73)/N73,0) -> 0.15789474
A73: JNJ | B73: =YEAR(E73) -> 2005 | C73: =MONTH(E73) -> 2 | D73: =A73&B73&C73 -> JNJ20052 | E73: 38394 | F73: 0.285 | G73: 38419 | H73: 0.0172 | I73: 0 | J73: 0 | K73: =IF(YEAR(E73)=YEAR(E74),YEAR(E73),0) -> 0 | L73: =IF(K73=0,K72,0) -> 2005 | M73: =A73&L73 -> JNJ2005 | N73: =F73 -> 0.285 | O73: =H73 -> 0.0172 | P73: =IF(S73>0,SUM(O73:O76)/4,0) -> 0 | Q73: =IF(K73=0,IF(A70=A73,AVERAGE(O70:O73),"x"),0) -> 0.018475 | R73: =IF(IF(L73-2000,)*L73>2005,AVERAGE(O70:O89),0) -> 0 | S73: =IF(A73=A74,(N73-N74)/N74,0) -> 0 | T73: =IF(L73>2005,(((N73-N93)/N93)+1)^(1/5)-1,0) -> 0 | U73: =IF(T73>0,R73+T73,0) -> 0 | V73: =IF(U73>0,(1+T73)*(1-((1+T73)/(1+U73))^5)/(U73-T73),0) -> 0 | W73: =IF(A73=A74,N73-N74,0) -> 0 | X73: =IF(A73=A74,(N73-N74)/N74,0) -> 0
A74: JNJ | B74: =YEAR(E74) -> 2004 | C74: =MONTH(E74) -> 11 | D74: =A74&B74&C74 -> JNJ200411 | E74: 38303 | F74: 0.285 | G74: 38328 | H74: 0.0181 | I74: 0 | J74: 0 | K74: =IF(YEAR(E74)=YEAR(E75),YEAR(E74),0) -> 2004 | L74: =IF(K74=0,K73,0) -> 0 | M74: =A74&L74 -> JNJ0 | N74: =F74 -> 0.285 | O74: =H74 -> 0.0181 | P74: =IF(S74>0,SUM(O74:O77)/4,0) -> 0 | Q74: =IF(K74=0,IF(A71=A74,AVERAGE(O71:O74),"x"),0) -> 0 | R74: =IF(L74>2005,AVERAGE(O71:O90),0) -> 0 | S74: =IF(A74=A75,(N74-N75)/N75,0) -> 0 | T74: =IF(L74>2005,(((N74-N94)/N94)+1)^(1/5)-1,0) -> 0 | U74: =IF(T74>0,R74+T74,0) -> 0 | V74: =IF(U74>0,(1+T74)*(1-((1+T74)/(1+U74))^5)/(U74-T74),0) -> 0 | W74: =IF(A74=A75,N74-N75,0) -> 0 | X74: =IF(A74=A75,(N74-N75)/N75,0) -> 0
A75: JNJ | B75: =YEAR(E75) -> 2004 | C75: =MONTH(E75) -> 8 | D75: =A75&B75&C75 -> JNJ20048 | E75: 38212 | F75: 0.285 | G75: 38237 | H75: 0.0187 | I75: 0 | J75: 0 | K75: =IF(YEAR(E75)=YEAR(E76),YEAR(E75),0) -> 2004 | L75: =IF(K75=0,K74,0) -> 0 | M75: =A75&L75 -> JNJ0 | N75: =F75 -> 0.285 | O75: =H75 -> 0.0187 | P75: =IF(S75>0,SUM(O75:O78)/4,0) -> 0 | Q75: =IF(K75=0,IF(A72=A75,AVERAGE(O72:O75),"x"),0) -> 0 | R75: =IF(L75>2005,AVERAGE(O72:O91),0) -> 0 | S75: =IF(A75=A76,(N75-N76)/N76,0) -> 0 | T75: =IF(L75>2005,(((N75-N95)/N95)+1)^(1/5)-1,0) -> 0 | U75: =IF(T75>0,R75+T75,0) -> 0 | V75: =IF(U75>0,(1+T75)*(1-((1+T75)/(1+U75))^5)/(U75-T75),0) -> 0 | W75: =IF(A75=A76,N75-N76,0) -> 0 | X75: =IF(A75=A76,(N75-N76)/N76,0) -> 0
A76: JNJ | B76: =YEAR(E76) -> 2004 | C76: =MONTH(E76) -> 5 | D76: =A76&B76&C76 -> JNJ20045 | E76: 38121 | F76: 0.285 | G76: 38146 | H76: 0.0183 | I76: 0.1875 | J76: 0.045 | K76: =IF(YEAR(E76)=YEAR(E77),YEAR(E76),0) -> 2004 | L76: =IF(K76=0,K75,0) -> 0 | M76: =A76&L76 -> JNJ0 | N76: =F76 -> 0.285 | O76: =H76 -> 0.0183 | P76: =IF(S76>0,SUM(O76:O79)/4,0) -> 0.01795 | Q76: =IF(K76=0,IF(A73=A76,AVERAGE(O73:O76),"x"),0) -> 0 | R76: =IF(L76>2005,AVERAGE(O73:O92),0) -> 0 | S76: =IF(A76=A77,(N76-N77)/N77,0) -> 0.1875 | T76: =IF(L76>2005,(((N76-N96)/N96)+1)^(1/5)-1,0) -> 0 | U76: =IF(T76>0,R76+T76,0) -> 0 | V76: =IF(U76>0,(1+T76)*(1-((1+T76)/(1+U76))^5)/(U76-T76),0) -> 0 | W76: =IF(A76=A77,N76-N77,0) -> 0.045 | X76: =IF(A76=A77,(N76-N77)/N77,0) -> 0.1875
A77: JNJ | B77: =YEAR(E77) -> 2004 | C77: =MONTH(E77) -> 2 | D77: =A77&B77&C77 -> JNJ20042 | E77: 38029 | F77: 0.24 | G77: 38055 | H77: 0.0176 | I77: 0 | J77: 0 | K77: =IF(YEAR(E77)=YEAR(E78),YEAR(E77),0) -> 0 | L77: =IF(K77=0,K76,0) -> 2004 | M77: =A77&L77 -> JNJ2004 | N77: =F77 -> 0.24 | O77: =H77 -> 0.0176 | P77: =IF(S77>0,SUM(O77:O80)/4,0) -> 0 | Q77: =IF(K77=0,IF(A74=A77,AVERAGE(O74:O77),"x"),0) -> 0.018175 | R77: =IF(L77>2005,AVERAGE(O74:O93),0) -> 0 | S77: =IF(A77=A78,(N77-N78)/N78,0) -> 0 | T77: =IF(L77>2005,(((N77-N97)/N97)+1)^(1/5)-1,0) -> 0 | U77: =IF(T77>0,R77+T77,0) -> 0 | V77: =IF(U77>0,(1+T77)*(1-((1+T77)/(1+U77))^5)/(U77-T77),0) -> 0 | W77: =IF(A77=A78,N77-N78,0) -> 0 | X77: =IF(A77=A78,(N77-N78)/N78,0) -> 0
A78: JNJ | B78: =YEAR(E78) -> 2003 | C78: =MONTH(E78) -> 11 | D78: =A78&B78&C78 -> JNJ200311 | E78: 37939 | F78: 0.24 | G78: 37964 | H78: 0.0184 | I78: 0 | J78: 0 | K78: =IF(YEAR(E78)=YEAR(E79),YEAR(E78),0) -> 2003 | L78: =IF(K78=0,K77,0) -> 0 | M78: =A78&L78 -> JNJ0 | N78: =F78 -> 0.24 | O78: =H78 -> 0.0184 | P78: =IF(S78>0,SUM(O78:O81)/4,0) -> 0 | Q78: =IF(K78=0,IF(A75=A78,AVERAGE(O75:O78),"x"),0) -> 0 | R78: =IF(L78>2005,AVERAGE(O75:O94),0) -> 0 | S78: =IF(A78=A79,(N78-N79)/N79,0) -> 0 | T78: =IF(L78>2005,(((N78-N98)/N98)+1)^(1/5)-1,0) -> 0 | U78: =IF(T78>0,R78+T78,0) -> 0 | V78: =IF(U78>0,(1+T78)*(1-((1+T78)/(1+U78))^5)/(U78-T78),0) -> 0 | W78: =IF(A78=A79,N78-N79,0) -> 0 | X78: =IF(A78=A79,(N78-N79)/N79,0) -> 0
A79: JNJ | B79: =YEAR(E79) -> 2003 | C79: =MONTH(E79) -> 8 | D79: =A79&B79&C79 -> JNJ20038 | E79: 37848 | F79: 0.24 | G79: 37873 | H79: 0.0175 | I79: 0 | J79: 0 | K79: =IF(YEAR(E79)=YEAR(E80),YEAR(E79),0) -> 2003 | L79: =IF(K79=0,K78,0) -> 0 | M79: =A79&L79 -> JNJ0 | N79: =F79 -> 0.24 | O79: =H79 -> 0.0175 | P79: =IF(S79>0,SUM(O79:O82)/4,0) -> 0 | Q79: =IF(K79=0,IF(A76=A79,AVERAGE(O76:O79),"x"),0) -> 0 | R79: =IF(L79>2005,AVERAGE(O76:O95),0) -> 0 | S79: =IF(A79=A80,(N79-N80)/N80,0) -> 0 | T79: =IF(L79>2005,(((N79-N99)/N99)+1)^(1/5)-1,0) -> 0 | U79: =IF(T79>0,R79+T79,0) -> 0 | V79: =IF(U79>0,(1+T79)*(1-((1+T79)/(1+U79))^5)/(U79-T79),0) -> 0 | W79: =IF(A79=A80,N79-N80,0) -> 0 | X79: =IF(A79=A80,(N79-N80)/N80,0) -> 0
A80: JNJ | B80: =YEAR(E80) -> 2003 | C80: =MONTH(E80) -> 5 | D80: =A80&B80&C80 -> JNJ20035 | E80: 37757 | F80: 0.24 | G80: 37782 | H80: 0.0154 | I80: 0.17073171 | J80: 0.035 | K80: =IF(YEAR(E80)=YEAR(E81),YEAR(E80),0) -> 2003 | L80: =IF(K80=0,K79,0) -> 0 | M80: =A80&L80 -> JNJ0 | N80: =F80 -> 0.24 | O80: =H80 -> 0.0154 | P80: =IF(S80>0,SUM(O80:O83)/4,0) -> 0.014675 | Q80: =IF(K80=0,IF(A77=A80,AVERAGE(O77:O80),"x"),0) -> 0 | R80: =IF(L80>2005,AVERAGE(O77:O96),0) -> 0 | S80: =IF(A80=A81,(N80-N81)/N81,0) -> 0.17073171 | T80: =IF(L80>2005,(((N80-N100)/N100)+1)^(1/5)-1,0) -> 0 | U80: =IF(T80>0,R80+T80,0) -> 0 | V80: =IF(U80>0,(1+T80)*(1-((1+T80)/(1+U80))^5)/(U80-T80),0) -> 0 | W80: =IF(A80=A81,N80-N81,0) -> 0.035 | X80: =IF(A80=A81,(N80-N81)/N81,0) -> 0.17073171
A81: JNJ | B81: =YEAR(E81) -> 2003 | C81: =MONTH(E81) -> 2 | D81: =A81&B81&C81 -> JNJ20032 | E81: 37665 | F81: 0.205 | G81: 37691 | H81: 0.0164 | I81: 0 | J81: 0 | K81: =IF(YEAR(E81)=YEAR(E82),YEAR(E81),0) -> 0 | L81: =IF(K81=0,K80,0) -> 2003 | M81: =A81&L81 -> JNJ2003 | N81: =F81 -> 0.205 | O81: =H81 -> 0.0164 | P81: =IF(S81>0,SUM(O81:O84)/4,0) -> 0 | Q81: =IF(K81=0,IF(A78=A81,AVERAGE(O78:O81),"x"),0) -> 0.016925 | R81: =IF(L81>2005,AVERAGE(O78:O97),0) -> 0 | S81: =IF(A81=A82,(N81-N82)/N82,0) -> 0 | T81: =IF(L81>2005,(((N81-N101)/N101)+1)^(1/5)-1,0) -> 0 | U81: =IF(T81>0,R81+T81,0) -> 0 | V81: =IF(U81>0,(1+T81)*(1-((1+T81)/(1+U81))^5)/(U81-T81),0) -> 0 | W81: =IF(A81=A82,N81-N82,0) -> 0 | X81: =IF(A81=A82,(N81-N82)/N82,0) -> 0
A82: JNJ | B82: =YEAR(E82) -> 2002 | C82: =MONTH(E82) -> 11 | D82: =A82&B82&C82 -> JNJ200211 | E82: 37575 | F82: 0.205 | G82: 37600 | H82: 0.0131 | I82: 0 | J82: 0 | K82: =IF(YEAR(E82)=YEAR(E83),YEAR(E82),0) -> 2002 | L82: =IF(K82=0,K81,0) -> 0 | M82: =A82&L82 -> JNJ0 | N82: =F82 -> 0.205 | O82: =H82 -> 0.0131 | P82: =IF(S82>0,SUM(O82:O85)/4,0) -> 0 | Q82: =IF(K82=0,IF(A79=A82,AVERAGE(O79:O82),"x"),0) -> 0 | R82: =IF(L82>2005,AVERAGE(O79:O98),0) -> 0 | S82: =IF(A82=A83,(N82-N83)/N83,0) -> 0 | T82: =IF(L82>2005,(((N82-N102)/N102)+1)^(1/5)-1,0) -> 0 | U82: =IF(T82>0,R82+T82,0) -> 0 | V82: =IF(U82>0,(1+T82)*(1-((1+T82)/(1+U82))^5)/(U82-T82),0) -> 0 | W82: =IF(A82=A83,N82-N83,0) -> 0 | X82: =IF(A82=A83,(N82-N83)/N83,0) -> 0
A83: JNJ | B83: =YEAR(E83) -> 2002 | C83: =MONTH(E83) -> 8 | D83: =A83&B83&C83 -> JNJ20028 | E83: 37484 | F83: 0.205 | G83: 37509 | H83: 0.0138 | I83: 0 | J83: 0 | K83: =IF(YEAR(E83)=YEAR(E84),YEAR(E83),0) -> 2002 | L83: =IF(K83=0,K82,0) -> 0 | M83: =A83&L83 -> JNJ0 | N83: =F83 -> 0.205 | O83: =H83 -> 0.0138 | P83: =IF(S83>0,SUM(O83:O86)/4,0) -> 0 | Q83: =IF(K83=0,IF(A80=A83,AVERAGE(O80:O83),"x"),0) -> 0 | R83: =IF(L83>2005,AVERAGE(O80:O99),0) -> 0 | S83: =IF(A83=A84,(N83-N84)/N84,0) -> 0 | T83: =IF(L83>2005,(((N83-N103)/N103)+1)^(1/5)-1,0) -> 0 | U83: =IF(T83>0,R83+T83,0) -> 0 | V83: =IF(U83>0,(1+T83)*(1-((1+T83)/(1+U83))^5)/(U83-T83),0) -> 0 | W83: =IF(A83=A84,N83-N84,0) -> 0 | X83: =IF(A83=A84,(N83-N84)/N84,0) -> 0
A84: JNJ | B84: =YEAR(E84) -> 2002 | C84: =MONTH(E84) -> 5 | D84: =A84&B84&C84 -> JNJ20025 | E84: 37393 | F84: 0.205 | G84: 37418 | H84: 0.0123 | I84: 0.13888889 | J84: 0.025 | K84: =IF(YEAR(E84)=YEAR(E85),YEAR(E84),0) -> 2002 | L84: =IF(K84=0,K83,0) -> 0 | M84: =A84&L84 -> JNJ0 | N84: =F84 -> 0.205 | O84: =H84 -> 0.0123 | P84: =IF(S84>0,SUM(O84:O87)/4,0) -> 0.0122 | Q84: =IF(K84=0,IF(A81=A84,AVERAGE(O81:O84),"x"),0) -> 0 | R84: =IF(L84>2005,AVERAGE(O81:O100),0) -> 0 | S84: =IF(A84=A85,(N84-N85)/N85,0) -> 0.13888889 | T84: =IF(L84>2005,(((N84-N104)/N104)+1)^(1/5)-1,0) -> 0 | U84: =IF(T84>0,R84+T84,0) -> 0 | V84: =IF(U84>0,(1+T84)*(1-((1+T84)/(1+U84))^5)/(U84-T84),0) -> 0 | W84: =IF(A84=A85,N84-N85,0) -> 0.025 | X84: =IF(A84=A85,(N84-N85)/N85,0) -> 0.13888889
A85: JNJ | B85: =YEAR(E85) -> 2002 | C85: =MONTH(E85) -> 2 | D85: =A85&B85&C85 -> JNJ20022 | E85: 37301 | F85: 0.18 | G85: 37327 | H85: 0.0124 | I85: 0 | J85: 0 | K85: =IF(YEAR(E85)=YEAR(E86),YEAR(E85),0) -> 0 | L85: =IF(K85=0,K84,0) -> 2002 | M85: =A85&L85 -> JNJ2002 | N85: =F85 -> 0.18 | O85: =H85 -> 0.0124 | P85: =IF(S85>0,SUM(O85:O88)/4,0) -> 0 | Q85: =IF(K85=0,IF(A82=A85,AVERAGE(O82:O85),"x"),0) -> 0.0129 | R85: =IF(L85>2005,AVERAGE(O82:O101),0) -> 0 | S85: =IF(A85=A86,(N85-N86)/N86,0) -> 0 | T85: =IF(L85>2005,(((N85-N105)/N105)+1)^(1/5)-1,0) -> 0 | U85: =IF(T85>0,R85+T85,0) -> 0 | V85: =IF(U85>0,(1+T85)*(1-((1+T85)/(1+U85))^5)/(U85-T85),0) -> 0 | W85: =IF(A85=A86,N85-N86,0) -> 0 | X85: =IF(A85=A86,(N85-N86)/N86,0) -> 0
... A87: JNJ | B87: =YEAR(E87) -> 2001 | C87: =MONTH(E87) -> 8 | D87: =A87&B87&C87 -> JNJ20018 | E87: 37120 | F87: 0.18 | G87: 37145 | H87: 0.0124 | I87: -0.5 | J87: -0.18 | K87: =IF(YEAR(E87)=YEAR(E88),YEAR(E87),0) -> 2001 | L87: =IF(K87=0,K86,0) -> 0 | M87: =A87&L87 -> JNJ0 | N87: =F87 -> 0.18 | O87: =H87 -> 0.0124 | P87: =IF(S87>0,SUM(O87:O90)/4,0) -> 0 | Q87: =IF(K87=0,IF(A84=A87,AVERAGE(O84:O87),"x"),0) -> 0 | R87: =IF(L87>2005,AVERAGE(O84:O103),0) -> 0 | S87: =IF(A87=A88,(N87-N88)/N88,0) -> 0 | T87: =IF(L87>2005,(((N87-N107)/N107)+1)^(1/5)-1,0) -> 0 | U87: =IF(T87>0,R87+T87,0) -> 0 | V87: =IF(U87>0,(1+T87)*(1-((1+T87)/(1+U87))^5)/(U87-T87),0) -> 0 | W87: =IF(A87=A88,N87-N88,0) -> 0 | X87: =IF(A87=A88,(N87-N88)/N88,0) -> 0
A88: JNJ | B88: =YEAR(E88) -> 2001 | C88: =MONTH(E88) -> 5 | D88: =A88&B88&C88 -> JNJ20015 | E88: 37029 | F88: 0.36 | G88: 37054 | H88: 0.0131 | I88: 0.125 | J88: 0.04 | K88: =IF(YEAR(E88)=YEAR(E89),YEAR(E88),0) -> 2001 | L88: =IF(K88=0,K87,0) -> 0 | M88: =A88&L88 -> JNJ0 | N88: =F88/2 -> 0.18 | O88: =H88 -> 0.0131 | P88: =IF(S88>0,SUM(O88:O91)/4,0) -> 0.013025 | Q88: =IF(K88=0,IF(A85=A88,AVERAGE(O85:O88),"x"),0) -> 0 | R88: =IF(L88>2005,AVERAGE(O85:O104),0) -> 0 | S88: =IF(A88=A89,(N88-N89)/N89,0) -> 0.125 | T88: =IF(L88>2005,(((N88-N108)/N108)+1)^(1/5)-1,0) -> 0 | U88: =IF(T88>0,R88+T88,0) -> 0 | V88: =IF(U88>0,(1+T88)*(1-((1+T88)/(1+U88))^5)/(U88-T88),0) -> 0 | W88: =IF(A88=A89,N88-N89,0) -> 0.02 | X88: =IF(A88=A89,(N88-N89)/N89,0) -> 0.125
A89: JNJ | B89: =YEAR(E89) -> 2001 | C89: =MONTH(E89) -> 2 | D89: =A89&B89&C89 -> JNJ20012 | E89: 36937 | F89: 0.32 | G89: 36963 | H89: 0.0134 | I89: 0 | J89: 0 | K89: =IF(YEAR(E89)=YEAR(E90),YEAR(E89),0) -> 0 | L89: =IF(K89=0,K88,0) -> 2001 | M89: =A89&L89 -> JNJ2001 | N89: =F89/2 -> 0.16 | O89: =H89 -> 0.0134 | P89: =IF(S89>0,SUM(O89:O92)/4,0) -> 0 | Q89: =IF(K89=0,IF(A86=A89,AVERAGE(O86:O89),"x"),0) -> 0.01265 | R89: =IF(L89>2005,AVERAGE(O86:O105),0) -> 0 | S89: =IF(A89=A90,(N89-N90)/N90,0) -> 0 | T89: =IF(L89>2005,(((N89-N109)/N109)+1)^(1/5)-1,0) -> 0 | U89: =IF(T89>0,R89+T89,0) -> 0 | V89: =IF(U89>0,(1+T89)*(1-((1+T89)/(1+U89))^5)/(U89-T89),0) -> 0 | W89: =IF(A89=A90,N89-N90,0) -> 0 | X89: =IF(A89=A90,(N89-N90)/N90,0) -> 0
A90: JNJ | B90: =YEAR(E90) -> 2000 | C90: =MONTH(E90) -> 11 | D90: =A90&B90&C90 -> JNJ200011 | E90: 36847 | F90: 0.32 | G90: 36872 | H90: 0.0132 | I90: 0 | J90: 0 | K90: =IF(YEAR(E90)=YEAR(E91),YEAR(E90),0) -> 2000 | L90: =IF(K90=0,K89,0) -> 0 | M90: =A90&L90 -> JNJ0 | N90: =F90/2 -> 0.16 | O90: =H90 -> 0.0132 | P90: =IF(S90>0,SUM(O90:O93)/4,0) -> 0 | Q90: =IF(K90=0,IF(A87=A90,AVERAGE(O87:O90),"x"),0) -> 0 | R90: =IF(L90>2005,AVERAGE(O87:O106),0) -> 0 | S90: =IF(A90=A91,(N90-N91)/N91,0) -> 0 | T90: =IF(L90>2005,(((N90-N110)/N110)+1)^(1/5)-1,0) -> 0 | U90: =IF(T90>0,R90+T90,0) -> 0 | V90: =IF(U90>0,(1+T90)*(1-((1+T90)/(1+U90))^5)/(U90-T90),0) -> 0 | W90: =IF(A90=A91,N90-N91,0) -> 0 | X90: =IF(A90=A91,(N90-N91)/N91,0) -> 0
A91: JNJ | B91: =YEAR(E91) -> 2000 | C91: =MONTH(E91) -> 8 | D91: =A91&B91&C91 -> JNJ20008 | E91: 36756 | F91: 0.32 | G91: 36781 | H91: 0.0124 | I91: 0 | J91: 0 | K91: =IF(YEAR(E91)=YEAR(E92),YEAR(E91),0) -> 2000 | L91: =IF(K91=0,K90,0) -> 0 | M91: =A91&L91 -> JNJ0 | N91: =F91/2 -> 0.16 | O91: =H91 -> 0.0124 | P91: =IF(S91>0,SUM(O91:O94)/4,0) -> 0 | Q91: =IF(K91=0,IF(A88=A91,AVERAGE(O88:O91),"x"),0) -> 0 | R91: =IF(L91>2005,AVERAGE(O88:O107),0) -> 0 | S91: =IF(A91=A92,(N91-N92)/N92,0) -> 0 | T91: =IF(L91>2005,(((N91-N111)/N111)+1)^(1/5)-1,0) -> 0 | U91: =IF(T91>0,R91+T91,0) -> 0 | V91: =IF(U91>0,(1+T91)*(1-((1+T91)/(1+U91))^5)/(U91-T91),0) -> 0 | W91: =IF(A91=A92,N91-N92,0) -> 0 | X91: =IF(A91=A92,(N91-N92)/N92,0) -> 0
A92: JNJ | B92: =YEAR(E92) -> 2000 | C92: =MONTH(E92) -> 5 | D92: =A92&B92&C92 -> JNJ20005 | E92: 36665 | F92: 0.32 | G92: 36690 | H92: 0.0131 | I92: 0.14285714 | J92: 0.04 | K92: =IF(YEAR(E92)=YEAR(E93),YEAR(E92),0) -> 2000 | L92: =IF(K92=0,K91,0) -> 0 | M92: =A92&L92 -> JNJ0 | N92: =F92/2 -> 0.16 | O92: =H92 -> 0.0131 | P92: =IF(S92>0,SUM(O92:O95)/4,0) -> 0.0179 | Q92: =IF(K92=0,IF(A89=A92,AVERAGE(O89:O92),"x"),0) -> 0 | R92: =IF(L92>2005,AVERAGE(O89:O108),0) -> 0 | S92: =IF(A92=A93,(N92-N93)/N93,0) -> 0.14285714 | T92: =IF(L92>2005,(((N92-N112)/N112)+1)^(1/5)-1,0) -> 0 | U92: =IF(T92>0,R92+T92,0) -> 0 | V92: =IF(U92>0,(1+T92)*(1-((1+T92)/(1+U92))^5)/(U92-T92),0) -> 0 | W92: =IF(A92=A93,N92-N93,0) -> 0.02 | X92: =IF(A92=A93,(N92-N93)/N93,0) -> 0.14285714
A93: JNJ | B93: =YEAR(E93) -> 2000 | C93: =MONTH(E93) -> 2 | D93: =A93&B93&C93 -> JNJ20002 | E93: 36567 | F93: 0.28 | G93: 36592 | H93: 0.0144 | I93: 0 | J93: 0 | K93: =IF(YEAR(E93)=YEAR(E94),YEAR(E93),0) -> 0 | L93: =IF(K93=0,K92,0) -> 2000 | M93: =A93&L93 -> JNJ2000 | N93: =F93/2 -> 0.14 | O93: =H93 -> 0.0144 | P93: =IF(S93>0,SUM(O93:O96)/4,0) -> 0 | Q93: =IF(K93=0,IF(A90=A93,AVERAGE(O90:O93),"x"),0) -> 0.013275 | R93: =IF(L93>2005,AVERAGE(O90:O109),0) -> 0 | S93: =IF(A93=A94,(N93-N94)/N94,0) -> 0 | T93: =IF(L93>2005,(((N93-N113)/N113)+1)^(1/5)-1,0) -> 0 | U93: =IF(T93>0,R93+T93,0) -> 0 | V93: =IF(U93>0,(1+T93)*(1-((1+T93)/(1+U93))^5)/(U93-T93),0) -> 0 | W93: =IF(A93=A94,N93-N94,0) -> 0 | X93: =IF(A93=A94,(N93-N94)/N94,0) -> 0
A94: HRL | B94: =YEAR(E94) -> 2022 | C94: =MONTH(E94) -> 10 | D94: =A94&B94&C94 -> HRL202210 | E94: 44848 | F94: 0.26 | G94: 44880 | H94: 0.0226 | I94: 0 | J94: 0 | K94: =IF(YEAR(E94)=YEAR(E95),YEAR(E94),0) -> 2022 | L94: =IF(K94=0,K93,0) -> 0 | M94: =A94&L94 -> HRL0 | N94: =F94 -> 0.26 | O94: =H94 -> 0.0226 | P94: =IF(S94>0,SUM(O94:O97)/4,0) -> 0 | Q94: =IF(K94=0,IF(A91=A94,AVERAGE(O91:O94),"x"),0) -> 0 | R94: =IF(L94>2005,AVERAGE(O91:O110),0) -> 0 | S94: =IF(A94=A95,(N94-N95)/N95,0) -> 0 | T94: =IF(L94>2005,(((N94-N114)/N114)+1)^(1/5)-1,0) -> 0 | U94: =IF(T94>0,R94+T94,0) -> 0 | V94: =IF(U94>0,(1+T94)*(1-((1+T94)/(1+U94))^5)/(U94-T94),0) -> 0 | W94: =IF(A94=A95,N94-N95,0) -> 0 | X94: =IF(A94=A95,(N94-N95)/N95,0) -> 0
A95: HRL | B95: =YEAR(E95) -> 2022 | C95: =MONTH(E95) -> 7 | D95: =A95&B95&C95 -> HRL20227 | E95: 44750 | F95: 0.26 | G95: 44788 | H95: 0.0215 | I95: 0 | J95: 0 | K95: =IF(YEAR(E95)=YEAR(E96),YEAR(E95),0) -> 2022 | L95: =IF(K95=0,K94,0) -> 0 | M95: =A95&L95 -> HRL0 | N95: =F95 -> 0.26 | O95: =H95 -> 0.0215 | P95: =IF(S95>0,SUM(O95:O98)/4,0) -> 0 | Q95: =IF(K95=0,IF(A92=A95,AVERAGE(O92:O95),"x"),0) -> 0 | R95: =IF(L95>2005,AVERAGE(O92:O111),0) -> 0 | S95: =IF(A95=A96,(N95-N96)/N96,0) -> 0 | T95: =IF(L95>2005,(((N95-N115)/N115)+1)^(1/5)-1,0) -> 0 | U95: =IF(T95>0,R95+T95,0) -> 0 | V95: =IF(U95>0,(1+T95)*(1-((1+T95)/(1+U95))^5)/(U95-T95),0) -> 0 | W95: =IF(A95=A96,N95-N96,0) -> 0 | X95: =IF(A95=A96,(N95-N96)/N96,0) -> 0
A96: HRL | B96: =YEAR(E96) -> 2022 | C96: =MONTH(E96) -> 4 | D96: =A96&B96&C96 -> HRL20224 | E96: 44659 | F96: 0.26 | G96: 44697 | H96: 0.0197 | I96: 0 | J96: 0 | K96: =IF(YEAR(E96)=YEAR(E97),YEAR(E96),0) -> 2022 | L96: =IF(K96=0,K95,0) -> 0 | M96: =A96&L96 -> HRL0 | N96: =F96 -> 0.26 | O96: =H96 -> 0.0197 | P96: =IF(S96>0,SUM(O96:O99)/4,0) -> 0 | Q96: =IF(K96=0,IF(A93=A96,AVERAGE(O93:O96),"x"),0) -> 0 | R96: =IF(L96>2005,AVERAGE(O93:O112),0) -> 0 | S96: =IF(A96=A97,(N96-N97)/N97,0) -> 0 | T96: =IF(L96>2005,(((N96-N116)/N116)+1)^(1/5)-1,0) -> 0 | U96: =IF(T96>0,R96+T96,0) -> 0 | V96: =IF(U96>0,(1+T96)*(1-((1+T96)/(1+U96))^5)/(U96-T96),0) -> 0 | W96: =IF(A96=A97,N96-N97,0) -> 0 | X96: =IF(A96=A97,(N96-N97)/N97,0) -> 0
...

Sheet 성장률
A1: 연도 | B1: 월 | C1: WBA | D1: LEG | E1: BEN | F1: SWK | G1: XOM | H1: CVX | I1: BKH | J1: NFG | K1: CAT | L1: TGT | M1: ITW | N1: EMR | O1: APD | P1: PG | Q1: JNJ | R1: ATO | S1: GPC | T1: GD | U1: AOS | V1: HRL | W1: LOW | X1: PPG | Y1: PH | Z1: ABM | AA1: ADM | AB1: ABT | AC1: CWT | AD1: ADP | AE1: TNC | AF1: DOV
A2: 2022 | B2: 1 | C2: =VLOOKUP(C$1&$A2,배당편집!$M$2:$T$2710,8,FALSE) -> 0.049514448 | D2: =VLOOKUP(D$1&$A2,배당편집!$M$2:$T$2710,8,FALSE) -> 0.043167564 | E2: =VLOOKUP(E$1&$A2,배당편집!$M$2:$T$2710,8,FALSE) -> 0.077143588 | F2: =VLOOKUP(F$1&$A2,배당편집!$M$2:$T$2710,8,FALSE) -> 0.063750604 | G2: =VLOOKUP(G$1&$A2,배당편집!$M$2:$T$2710,8,FALSE) -> 0.032486262 | H2: =VLOOKUP(H$1&$A2,배당편집!$M$2:$T$2710,8,FALSE) -> 0.056265069 | I2: =VLOOKUP(I$1&$A2,배당편집!$M$2:$T$2710,8,FALSE) -> 0.059818243 | J2: =VLOOKUP(J$1&$A2,배당편집!$M$2:$T$2710,8,FALSE) -> 0.023555213 | ... AF2: =VLOOKUP(AF$1&$A2,배당편집!$M$2:$T$2710,8,FALSE) -> 0.025896305
A3: 2022 | B3: 2 | C3: =VLOOKUP(C$1&$A3,배당편집!$M$2:$T$2710,8,FALSE) -> 0.049514448 | D3: =VLOOKUP(D$1&$A3,배당편집!$M$2:$T$2710,8,FALSE) -> 0.043167564 | E3: =VLOOKUP(E$1&$A3,배당편집!$M$2:$T$2710,8,FALSE) -> 0.077143588 | F3: =VLOOKUP(F$1&$A3,배당편집!$M$2:$T$2710,8,FALSE) -> 0.063750604 | G3: =VLOOKUP(G$1&$A3,배당편집!$M$2:$T$2710,8,FALSE) -> 0.032486262 | H3: =VLOOKUP(H$1&$A3,배당편집!$M$2:$T$2710,8,FALSE) -> 0.056265069 | I3: =VLOOKUP(I$1&$A3,배당편집!$M$2:$T$2710,8,FALSE) -> 0.059818243 | J3: =VLOOKUP(J$1&$A3,배당편집!$M$2:$T$2710,8,FALSE) -> 0.023555213 | ... AF3: =VLOOKUP(AF$1&$A3,배당편집!$M$2:$T$2710,8,FALSE) -> 0.025896305
A4: 2022 | B4: 3 | C4: =VLOOKUP(C$1&$A4,배당편집!$M$2:$T$2710,8,FALSE) -> 0.049514448 | D4: =VLOOKUP(D$1&$A4,배당편집!$M$2:$T$2710,8,FALSE) -> 0.043167564 | E4: =VLOOKUP(E$1&$A4,배당편집!$M$2:$T$2710,8,FALSE) -> 0.077143588 | F4: =VLOOKUP(F$1&$A4,배당편집!$M$2:$T$2710,8,FALSE) -> 0.063750604 | G4: =VLOOKUP(G$1&$A4,배당편집!$M$2:$T$2710,8,FALSE) -> 0.032486262 | H4: =VLOOKUP(H$1&$A4,배당편집!$M$2:$T$2710,8,FALSE) -> 0.056265069 | I4: =VLOOKUP(I$1&$A4,배당편집!$M$2:$T$2710,8,FALSE) -> 0.059818243 | J4: =VLOOKUP(J$1&$A4,배당편집!$M$2:$T$2710,8,FALSE) -> 0.023555213 | ... AF4: =VLOOKUP(AF$1&$A4,배당편집!$M$2:$T$2710,8,FALSE) -> 0.025896305
A5: 2022 | B5: 4 | C5: =VLOOKUP(C$1&$A5,배당편집!$M$2:$T$2710,8,FALSE) -> 0.049514448 | D5: =VLOOKUP(D$1&$A5,배당편집!$M$2:$T$2710,8,FALSE) -> 0.043167564 | E5: =VLOOKUP(E$1&$A5,배당편집!$M$2:$T$2710,8,FALSE) -> 0.077143588 | F5: =VLOOKUP(F$1&$A5,배당편집!$M$2:$T$2710,8,FALSE) -> 0.063750604 | G5: =VLOOKUP(G$1&$A5,배당편집!$M$2:$T$2710,8,FALSE) -> 0.032486262 | H5: =VLOOKUP(H$1&$A5,배당편집!$M$2:$T$2710,8,FALSE) -> 0.056265069 | I5: =VLOOKUP(I$1&$A5,배당편집!$M$2:$T$2710,8,FALSE) -> 0.059818243 | J5: =VLOOKUP(J$1&$A5,배당편집!$M$2:$T$2710,8,FALSE) -> 0.023555213 | ... AF5: =VLOOKUP(AF$1&$A5,배당편집!$M$2:$T$2710,8,FALSE) -> 0.025896305
A6: 2022 | B6: 5 | C6: =VLOOKUP(C$1&$A6,배당편집!$M$2:$T$2710,8,FALSE) -> 0.049514448 | D6: =VLOOKUP(D$1&$A6,배당편집!$M$2:$T$2710,8,FALSE) -> 0.043167564 | E6: =VLOOKUP(E$1&$A6,배당편집!$M$2:$T$2710,8,FALSE) -> 0.077143588 | F6: =VLOOKUP(F$1&$A6,배당편집!$M$2:$T$2710,8,FALSE) -> 0.063750604 | G6: =VLOOKUP(G$1&$A6,배당편집!$M$2:$T$2710,8,FALSE) -> 0.032486262 | H6: =VLOOKUP(H$1&$A6,배당편집!$M$2:$T$2710,8,FALSE) -> 0.056265069 | I6: =VLOOKUP(I$1&$A6,배당편집!$M$2:$T$2710,8,FALSE) -> 0.059818243 | J6: =VLOOKUP(J$1&$A6,배당편집!$M$2:$T$2710,8,FALSE) -> 0.023555213 | ... AF6: =VLOOKUP(AF$1&$A6,배당편집!$M$2:$T$2710,8,FALSE) -> 0.025896305
A7: 2022 | B7: 6 | C7: =VLOOKUP(C$1&$A7,배당편집!$M$2:$T$2710,8,FALSE) -> 0.049514448 | D7: =VLOOKUP(D$1&$A7,배당편집!$M$2:$T$2710,8,FALSE) -> 0.043167564 | E7: =VLOOKUP(E$1&$A7,배당편집!$M$2:$T$2710,8,FALSE) -> 0.077143588 | F7: =VLOOKUP(F$1&$A7,배당편집!$M$2:$T$2710,8,FALSE) -> 0.063750604 | G7: =VLOOKUP(G$1&$A7,배당편집!$M$2:$T$2710,8,FALSE) -> 0.032486262 | H7: =VLOOKUP(H$1&$A7,배당편집!$M$2:$T$2710,8,FALSE) -> 0.056265069 | I7: =VLOOKUP(I$1&$A7,배당편집!$M$2:$T$2710,8,FALSE) -> 0.059818243 | J7: =VLOOKUP(J$1&$A7,배당편집!$M$2:$T$2710,8,FALSE) -> 0.023555213 | ... AF7: =VLOOKUP(AF$1&$A7,배당편집!$M$2:$T$2710,8,FALSE) -> 0.025896305
A8: 2022 | B8: 7 | C8: =VLOOKUP(C$1&$A8,배당편집!$M$2:$T$2710,8,FALSE) -> 0.049514448 | D8: =VLOOKUP(D$1&$A8,배당편집!$M$2:$T$2710,8,FALSE) -> 0.043167564 | E8: =VLOOKUP(E$1&$A8,배당편집!$M$2:$T$2710,8,FALSE) -> 0.077143588 | F8: =VLOOKUP(F$1&$A8,배당편집!$M$2:$T$2710,8,FALSE) -> 0.063750604 | G8: =VLOOKUP(G$1&$A8,배당편집!$M$2:$T$2710,8,FALSE) -> 0.032486262 | H8: =VLOOKUP(H$1&$A8,배당편집!$M$2:$T$2710,8,FALSE) -> 0.056265069 | I8: =VLOOKUP(I$1&$A8,배당편집!$M$2:$T$2710,8,FALSE) -> 0.059818243 | J8: =VLOOKUP(J$1&$A8,배당편집!$M$2:$T$2710,8,FALSE) -> 0.023555213 | ... AF8: =VLOOKUP(AF$1&$A8,배당편집!$M$2:$T$2710,8,FALSE) -> 0.025896305
A9: 2022 | B9: 8 | C9: =VLOOKUP(C$1&$A9,배당편집!$M$2:$T$2710,8,FALSE) -> 0.049514448 | D9: =VLOOKUP(D$1&$A9,배당편집!$M$2:$T$2710,8,FALSE) -> 0.043167564 | E9: =VLOOKUP(E$1&$A9,배당편집!$M$2:$T$2710,8,FALSE) -> 0.077143588 | F9: =VLOOKUP(F$1&$A9,배당편집!$M$2:$T$2710,8,FALSE) -> 0.063750604 | G9: =VLOOKUP(G$1&$A9,배당편집!$M$2:$T$2710,8,FALSE) -> 0.032486262 | H9: =VLOOKUP(H$1&$A9,배당편집!$M$2:$T$2710,8,FALSE) -> 0.056265069 | I9: =VLOOKUP(I$1&$A9,배당편집!$M$2:$T$2710,8,FALSE) -> 0.059818243 | J9: =VLOOKUP(J$1&$A9,배당편집!$M$2:$T$2710,8,FALSE) -> 0.023555213 | ... AF9: =VLOOKUP(AF$1&$A9,배당편집!$M$2:$T$2710,8,FALSE) -> 0.025896305
A10: 2022 | B10: 9 | C10: =VLOOKUP(C$1&$A10,배당편집!$M$2:$T$2710,8,FALSE) -> 0.049514448 | D10: =VLOOKUP(D$1&$A10,배당편집!$M$2:$T$2710,8,FALSE) -> 0.043167564 | E10: =VLOOKUP(E$1&$A10,배당편집!$M$2:$T$2710,8,FALSE) -> 0.077143588 | F10: =VLOOKUP(F$1&$A10,배당편집!$M$2:$T$2710,8,FALSE) -> 0.063750604 | G10: =VLOOKUP(G$1&$A10,배당편집!$M$2:$T$2710,8,FALSE) -> 0.032486262 | H10: =VLOOKUP(H$1&$A10,배당편집!$M$2:$T$2710,8,FALSE) -> 0.056265069 | I10: =VLOOKUP(I$1&$A10,배당편집!$M$2:$T$2710,8,FALSE) -> 0.059818243 | J10: =VLOOKUP(J$1&$A10,배당편집!$M$2:$T$2710,8,FALSE) -> 0.023555213 | ... AF10: =VLOOKUP(AF$1&$A10,배당편집!$M$2:$T$2710,8,FALSE) -> 0.025896305
A11: 2022 | B11: 10 | C11: =VLOOKUP(C$1&$A11,배당편집!$M$2:$T$2710,8,FALSE) -> 0.049514448 | D11: =VLOOKUP(D$1&$A11,배당편집!$M$2:$T$2710,8,FALSE) -> 0.043167564 | E11: =VLOOKUP(E$1&$A11,배당편집!$M$2:$T$2710,8,FALSE) -> 0.077143588 | F11: =VLOOKUP(F$1&$A11,배당편집!$M$2:$T$2710,8,FALSE) -> 0.063750604 | G11: =VLOOKUP(G$1&$A11,배당편집!$M$2:$T$2710,8,FALSE) -> 0.032486262 | H11: =VLOOKUP(H$1&$A11,배당편집!$M$2:$T$2710,8,FALSE) -> 0.056265069 | I11: =VLOOKUP(I$1&$A11,배당편집!$M$2:$T$2710,8,FALSE) -> 0.059818243 | J11: =VLOOKUP(J$1&$A11,배당편집!$M$2:$T$2710,8,FALSE) -> 0.023555213 | ... AF11: =VLOOKUP(AF$1&$A11,배당편집!$M$2:$T$2710,8,FALSE) -> 0.025896305
A12: 2022 | B12: 11 | C12: =VLOOKUP(C$1&$A12,배당편집!$M$2:$T$2710,8,FALSE) -> 0.049514448 | D12: =VLOOKUP(D$1&$A12,배당편집!$M$2:$T$2710,8,FALSE) -> 0.043167564 | E12: =VLOOKUP(E$1&$A12,배당편집!$M$2:$T$2710,8,FALSE) -> 0.077143588 | F12: =VLOOKUP(F$1&$A12,배당편집!$M$2:$T$2710,8,FALSE) -> 0.063750604 | G12: =VLOOKUP(G$1&$A12,배당편집!$M$2:$T$2710,8,FALSE) -> 0.032486262 | H12: =VLOOKUP(H$1&$A12,배당편집!$M$2:$T$2710,8,FALSE) -> 0.056265069 | I12: =VLOOKUP(I$1&$A12,배당편집!$M$2:$T$2710,8,FALSE) -> 0.059818243 | J12: =VLOOKUP(J$1&$A12,배당편집!$M$2:$T$2710,8,FALSE) -> 0.023555213 | ... AF12: =VLOOKUP(AF$1&$A12,배당편집!$M$2:$T$2710,8,FALSE) -> 0.025896305
A13: 2022 | B13: 12 | C13: =VLOOKUP(C$1&$A13,배당편집!$M$2:$T$2710,8,FALSE) -> 0.049514448 | D13: =VLOOKUP(D$1&$A13,배당편집!$M$2:$T$2710,8,FALSE) -> 0.043167564 | E13: =VLOOKUP(E$1&$A13,배당편집!$M$2:$T$2710,8,FALSE) -> 0.077143588 | F13: =VLOOKUP(F$1&$A13,배당편집!$M$2:$T$2710,8,FALSE) -> 0.063750604 | G13: =VLOOKUP(G$1&$A13,배당편집!$M$2:$T$2710,8,FALSE) -> 0.032486262 | H13: =VLOOKUP(H$1&$A13,배당편집!$M$2:$T$2710,8,FALSE) -> 0.056265069 | I13: =VLOOKUP(I$1&$A13,배당편집!$M$2:$T$2710,8,FALSE) -> 0.059818243 | J13: =VLOOKUP(J$1&$A13,배당편집!$M$2:$T$2710,8,FALSE) -> 0.023555213 | ... AF13: =VLOOKUP(AF$1&$A13,배당편집!$M$2:$T$2710,8,FALSE) -> 0.025896305
... A205: 2006 | B205: 12 | C205: =VLOOKUP(C$1&$A205,배당편집!$M$2:$T$2710,8,FALSE) -> 0.13179837 | D205: =VLOOKUP(D$1&$A205,배당편집!$M$2:$T$2710,8,FALSE) -> 0.059223841 | E205: =VLOOKUP(E$1&$A205,배당편집!$M$2:$T$2710,8,FALSE) -> 0.31950791 | F205: =VLOOKUP(F$1&$A205,배당편집!$M$2:$T$2710,8,FALSE) -> 0.047451764 | G205: =VLOOKUP(G$1&$A205,배당편집!$M$2:$T$2710,8,FALSE) -> 0.077818068 | H205: =VLOOKUP(H$1&$A205,배당편집!$M$2:$T$2710,8,FALSE) -> 0.067249182 | I205: =VLOOKUP(I$1&$A205,배당편집!$M$2:$T$2710,8,FALSE) -> 0.033406483 | J205: =VLOOKUP(J$1&$A205,배당편집!$M$2:$T$2710,8,FALSE) -> 0.038573773 | ... AF205: =VLOOKUP(AF$1&$A205,배당편집!$M$2:$T$2710,8,FALSE) -> 0.063427242

Sheet coeff
A1: 연도 | B1: WBA | C1: LEG | D1: BEN | E1: SWK | F1: XOM | G1: CVX | H1: BKH | I1: NFG | J1: CAT | K1: TGT | L1: ITW | M1: EMR | N1: APD | O1: PG | P1: JNJ | Q1: ATO | R1: GPC | S1: GD | T1: AOS | U1: HRL | V1: LOW | W1: PPG | X1: PH | Y1: ABM | Z1: ADM | AA1: ABT | AB1: CWT | AC1: ADP | AD1: TNC | AE1: DOV
A2: 2022 | B2: 4.5211875 | C2: 4.4865827 | D2: 4.5143405 | E2: 4.7227978 | F2: 4.3379435 | G2: 4.4353019 | H2: 4.5710162 | I2: 4.5261855 | J2: 4.6737685 | K2: 4.6878284 | L2: 4.6894805 | M2: 4.6419988 | N2: 4.7002466 | O2: 4.6359267 | P2: 4.646997 | Q2: 4.7081924 | R2: 4.6107854 | S2: 4.6927255 | T2: 4.7777203 | U2: 4.7291929 | V2: 4.7836159 | W2: 4.7716258 | X2: 4.7746079 | Y2: 4.7240782 | Z2: 4.61923 | AA2: 4.7875959 | AB2: 4.7724868 | AC2: 4.7266003 | AD2: 4.814263 | AE2: 4.7550549
A3: 2021 | B3: 4.5890231 | C3: 4.5269069 | D3: 4.5604588 | E3: 4.756236 | F3: 4.3285597 | G3: 4.4184 | H3: 4.5851129 | I3: 4.5333316 | J3: 4.6528747 | K3: 4.6230165 | L3: 4.70919 | M3: 4.6089123 | N3: 4.7003141 | O3: 4.6141386 | P3: 4.6488334 | Q3: 4.6994663 | R3: 4.5961824 | S3: 4.7066166 | T3: 4.8005452 | U3: 4.7358635 | V3: 4.7776006 | W3: 4.7800917 | X3: 4.7724104 | Y3: 4.7292922 | Z3: 4.59303 | AA3: 4.7709334 | AB3: 4.765166 | AC3: 4.7286025 | AD3: 4.8218897 | AE3: 4.737224
A4: 2020 | B4: 4.6393959 | C4: 4.5488555 | D4: 4.634775 | E4: 4.7461369 | F4: 4.3923174 | G4: 4.4362545 | H4: 4.5963606 | I4: 4.5417585 | J4: 4.6105443 | K4: 4.5796463 | L4: 4.7105327 | M4: 4.5679593 | N4: 4.6893537 | O4: 4.5929827 | P4: 4.6417989 | Q4: 4.7060607 | R4: 4.5979316 | S4: 4.7193334 | T4: 4.8185471 | U4: 4.7610533 | V4: 4.7768594 | W4: 4.7770573 | X4: 4.749016 | Y4: 4.7246326 | Z4: 4.5782952 | AA4: 4.7403144 | AB4: 4.7404492 | AC4: 4.7184915 | AD4: 4.8164542 | AE4: 4.7067474
A5: 2019 | B5: 4.7093996 | C5: 4.5842306 | D5: 4.7624902 | E5: 4.7399358 | F5: 4.4980546 | G5: 4.4604853 | H5: 4.5926031 | I5: 4.5792029 | J5: 4.5949528 | K5: 4.5743207 | L5: 4.7232423 | M5: 4.5613452 | N5: 4.6800969 | O5: 4.5764817 | P5: 4.6379189 | Q5: 4.691786 | R5: 4.6174843 | S5: 4.7450253 | T5: 4.8471033 | U5: 4.7946669 | V5: 4.7906605 | W5: 4.7940297 | X5: 4.7462095 | Y5: 4.7269281 | Z5: 4.6119126 | AA5: 4.7268972 | AB5: 4.709918 | AC5: 4.7141489 | AD5: 4.8200374 | AE5: 4.6913042
A6: 2018 | B6: 4.741146 | C6: 4.5891873 | D6: 4.8431751 | E6: 4.7308899 | F6: 4.5487202 | G6: 4.4783222 | H6: 4.588025 | I6: 4.6112964 | J6: 4.6059191 | K6: 4.5902308 | L6: 4.731565 | M6: 4.5735822 | N6: 4.6788197 | O6: 4.5724127 | P6: 4.6412157 | Q6: 4.6671475 | R6: 4.6320503 | S6: 4.7488769 | T6: 4.8686529 | U6: 4.8263411 | V6: 4.7987582 | W6: 4.8031883 | X6: 4.7542211 | Y6: 4.7212455 | Z6: 4.6621423 | AA6: 4.73688 | AB6: 4.6745449 | AC6: 4.6995529 | AD6: 4.8241061 | AE6: 4.7056626
A7: 2017 | B7: 4.7506349 | C7: 4.5801204 | D7: 4.9116914 | E7: 4.7208296 | F7: 4.5970782 | G7: 4.5008165 | H7: 4.5902254 | I7: 4.6352003 | J7: 4.6047133 | K7: 4.6261884 | L7: 4.7345472 | M7: 4.5765458 | N7: 4.6770109 | O7: 4.5871882 | P7: 4.6368274 | Q7: 4.63582 | R7: 4.6398626 | S7: 4.7174107 | T7: 4.8754382 | U7: 4.8563891 | V7: 4.8038887 | W7: 4.8042634 | X7: 4.7584812 | Y7: 4.7099033 | Z7: 4.6848714 | AA7: 4.7172426 | AB7: 4.641491 | AC7: 4.6903752 | AD7: 4.8218356 | AE7: 4.7191269
A8: 2016 | B8: 4.7427185 | C8: 4.5327783 | D8: 4.9526047 | E8: 4.6978946 | F8: 4.6333332 | G8: 4.5278503 | H8: 4.5466994 | I8: 4.6359647 | J8: 4.6305702 | K8: 4.6800651 | L8: 4.7145714 | M8: 4.589368 | N8: 4.6669061 | O8: 4.5891316 | P8: 4.612055 | Q8: 4.5842864 | R8: 4.6419227 | S8: 4.6902329 | T8: 4.86801 | U8: 4.8829288 | V8: 4.8047479 | W8: 4.7858979 | X8: 4.7598293 | Y8: 4.6799322 | Z8: 4.7012314 | AA8: 4.7013844 | AB8: 4.6023932 | AC8: 4.6756312 | AD8: 4.8085709 | AE8: 4.7245753
A9: 2015 | B9: 4.7500258 | C9: 4.4818296 | D9: 4.9680261 | E9: 4.7006739 | F9: 4.6611211 | G9: 4.5646628 | H9: 4.501835 | I9: 4.6540384 | J9: 4.680677 | K9: 4.7256985 | L9: 4.6986467 | M9: 4.6173661 | N9: 4.6718101 | O9: 4.5972204 | P9: 4.5966592 | Q9: 4.5367228 | R9: 4.6312116 | S9: 4.679752 | T9: 4.8768631 | U9: 4.8952417 | V9: 4.7982443 | W9: 4.7561691 | X9: 4.785096 | Y9: 4.6665723 | Z9: 4.7274277 | AA9: 4.6776996 | AB9: 4.5792069 | AC9: 4.6642931 | AD9: 4.8059185 | AE9: 4.73923
A10: 2014 | B10: 4.7531701 | C10: 4.4341578 | D10: 4.9702415 | E10: 4.6932239 | F10: 4.6750696 | G10: 4.58318 | H10: 4.4656555 | I10: 4.665791 | J10: 4.6975004 | K10: 4.7488308 | L10: 4.6781662 | M10: 4.6328446 | N10: 4.6712245 | O10: 4.6054956 | P10: 4.5850794 | Q10: 4.4850912 | R10: 4.6018432 | S10: 4.6662168 | T10: 4.7777203 | U10: 4.8886792 | V10: 4.7832904 | W10: 4.7027754 | X10: 4.7887976 | Y10: 4.66091 | Z10: 4.7313397 | AA10: 4.6528097 | AB10: 4.5684652 | AC10: 4.6428576 | AD10: 4.7893894 | AE10: 4.7445173
A11: 2013 | B11: 4.7651332 | C11: 4.3591043 | D11: 4.9670673 | E11: 4.6620087 | F11: 4.6883024 | G11: 4.577259 | H11: 4.384522 | I11: 4.6372992 | J11: 4.6633119 | K11: 4.7762057 | L11: 4.6482136 | M11: 4.6126174 | N11: 4.6606397 | O11: 4.6108618 | P11: 4.5737499 | Q11: 4.4283513 | R11: 4.5434231 | S11: 4.6499436 | T11: 4.8005452 | U11: 4.8766492 | V11: 4.7772945 | W11: 4.6176596 | X11: 4.7792121 | Y11: 4.6481948 | Z11: 4.7216755 | AA11: 4.5988148 | AB11: 4.5613225 | AC11: 4.6196992 | AD11: 4.7482682 | AE11: 4.7166847
A12: 2012 | B12: 4.7883479 | C12: 4.3632869 | D12: 4.9685476 | E12: 4.6385717 | F12: 4.7002293 | G12: 4.5830677 | H12: 4.3573624 | I12: 4.6199637 | J12: 4.660614 | K12: 4.7968569 | L12: 4.6523267 | M12: 4.62125 | N12: 4.6718758 | O12: 4.6329525 | P12: 4.5804343 | Q12: 4.3901832 | R12: 4.517206 | S12: 4.7027233 | T12: 4.8185471 | U12: 4.8757891 | V12: 4.7916559 | W12: 4.5664461 | X12: 4.8133009 | Y12: 4.6499436 | Z12: 4.7370978 | AA12: 4.6041018 | AB12: 4.5535267 | AC12: 4.623119 | AD12: 4.7402186 | AE12: 4.7063506
A13: 2011 | B13: 4.830557 | C13: 4.3967551 | D13: 4.9715291 | E13: 4.6489217 | F13: 4.7153246 | G13: 4.5960818 | H13: 4.385442 | I13: 4.6246373 | J13: 4.6765946 | K13: 4.8267945 | L13: 4.6854923 | M13: 4.6458549 | N13: 4.7038191 | O13: 4.663717 | P13: 4.61254 | Q13: 4.3854941 | R13: 4.51998 | S13: 4.7414126 | T13: 4.8471033 | U13: 4.878288 | V13: 4.862344 | W13: 4.5552666 | X13: 4.8272623 | Y13: 4.6759337 | Z13: 4.769721 | AA13: 4.6233198 | AB13: 4.5653733 | AC13: 4.6524562 | AD13: 4.7535285 | AE13: 4.7168096
... A18: 2006 | B18: 4.9353848 | C18: 4.6822317 | D18: 4.9816367 | E18: 4.6416346 | F18: 4.7011902 | G18: 4.5645841 | H18: 4.4753524 | I18: 4.4628977 | J18: 4.7200993 | K18: 4.9111422 | L18: 4.8252953 | M18: 4.62125 | N18: 4.7520454 | O18: 4.7546618 | P18: 4.7780088 | Q18: 4.3651256 | R18: 4.5683118 | S18: 4.8099187 | T18: 4.8222815 | U18: 4.8910153 | V18: 4.9685009 | W18: 4.5846019 | X18: 4.8076489 | Y18: 4.6933723 | Z18: 4.8092659 | AA18: 4.6932005 | AB18: 4.4885769 | AC18: 4.8299599 | AD18: 4.7039437 | AE18: 4.7835191

Sheet cons
A1: 연도 | B1: 월 | C1: WBA | D1: LEG | E1: BEN | F1: SWK | G1: XOM | H1: CVX | I1: BKH | J1: NFG | K1: CAT | L1: TGT | M1: ITW | N1: EMR | O1: APD | P1: PG | Q1: JNJ | R1: ATO | S1: GPC | T1: GD | U1: AOS | V1: HRL | W1: LOW | X1: PPG | Y1: PH | Z1: ABM | AA1: ADM | AB1: ABT | AC1: CWT | AD1: ADP | AE1: TNC | AF1: DOV
A2: 2022 | B2: 1 | C2: =IFERROR(VLOOKUP(C$1&$A2&$B2,배당편집!$D$2:$N$2710,11,FALSE), 0) -> 0 | D2: =IFERROR(VLOOKUP(D$1&$A2&$B2,배당편집!$D$2:$N$2710,11,FALSE), 0) -> 0 | E2: =IFERROR(VLOOKUP(E$1&$A2&$B2,배당편집!$D$2:$N$2710,11,FALSE), 0) -> 0 | F2: =IFERROR(VLOOKUP(F$1&$A2&$B2,배당편집!$D$2:$N$2710,11,FALSE), 0) -> 0 | G2: =IFERROR(VLOOKUP(G$1&$A2&$B2,배당편집!$D$2:$N$2710,11,FALSE), 0) -> 0 | H2: =IFERROR(VLOOKUP(H$1&$A2&$B2,배당편집!$D$2:$N$2710,11,FALSE), 0) -> 0 | I2: =IFERROR(VLOOKUP(I$1&$A2&$B2,배당편집!$D$2:$N$2710,11,FALSE), 0) -> 0 | J2: =IFERROR(VLOOKUP(J$1&$A2&$B2,배당편집!$D$2:$N$2710,11,FALSE), 0) -> 0 | ... AF2: =IFERROR(VLOOKUP(AF$1&$A2&$B2,배당편집!$D$2:$N$2710,11,FALSE), 0) -> 0
A3: 2022 | B3: 2 | C3: =IFERROR(VLOOKUP(C$1&$A3&$B3,배당편집!$D$2:$N$2710,11,FALSE), 0) -> 0.4775 | D3: =IFERROR(VLOOKUP(D$1&$A3&$B3,배당편집!$D$2:$N$2710,11,FALSE), 0) -> 0 | E3: =IFERROR(VLOOKUP(E$1&$A3&$B3,배당편집!$D$2:$N$2710,11,FALSE), 0) -> 0 | F3: =IFERROR(VLOOKUP(F$1&$A3&$B3,배당편집!$D$2:$N$2710,11,FALSE), 0) -> 0 | G3: =IFERROR(VLOOKUP(G$1&$A3&$B3,배당편집!$D$2:$N$2710,11,FALSE), 0) -> 0.88 | H3: =IFERROR(VLOOKUP(H$1&$A3&$B3,배당편집!$D$2:$N$2710,11,FALSE), 0) -> 1.42 | I3: =IFERROR(VLOOKUP(I$1&$A3&$B3,배당편집!$D$2:$N$2710,11,FALSE), 0) -> 0.595 | J3: =IFERROR(VLOOKUP(J$1&$A3&$B3,배당편집!$D$2:$N$2710,11,FALSE), 0) -> 0 | ... AF3: =IFERROR(VLOOKUP(AF$1&$A3&$B3,배당편집!$D$2:$N$2710,11,FALSE), 0) -> 0.5
A4: 2022 | B4: 3 | C4: =IFERROR(VLOOKUP(C$1&$A4&$B4,배당편집!$D$2:$N$2710,11,FALSE), 0) -> 0 | D4: =IFERROR(VLOOKUP(D$1&$A4&$B4,배당편집!$D$2:$N$2710,11,FALSE), 0) -> 0.42 | E4: =IFERROR(VLOOKUP(E$1&$A4&$B4,배당편집!$D$2:$N$2710,11,FALSE), 0) -> 0.29 | F4: =IFERROR(VLOOKUP(F$1&$A4&$B4,배당편집!$D$2:$N$2710,11,FALSE), 0) -> 0.79 | G4: =IFERROR(VLOOKUP(G$1&$A4&$B4,배당편집!$D$2:$N$2710,11,FALSE), 0) -> 0 | H4: =IFERROR(VLOOKUP(H$1&$A4&$B4,배당편집!$D$2:$N$2710,11,FALSE), 0) -> 0 | I4: =IFERROR(VLOOKUP(I$1&$A4&$B4,배당편집!$D$2:$N$2710,11,FALSE), 0) -> 0 | J4: =IFERROR(VLOOKUP(J$1&$A4&$B4,배당편집!$D$2:$N$2710,11,FALSE), 0) -> 0.455 | ... AF4: =IFERROR(VLOOKUP(AF$1&$A4&$B4,배당편집!$D$2:$N$2710,11,FALSE), 0) -> 0
A5: 2022 | B5: 4 | C5: =IFERROR(VLOOKUP(C$1&$A5&$B5,배당편집!$D$2:$N$2710,11,FALSE), 0) -> 0 | D5: =IFERROR(VLOOKUP(D$1&$A5&$B5,배당편집!$D$2:$N$2710,11,FALSE), 0) -> 0 | E5: =IFERROR(VLOOKUP(E$1&$A5&$B5,배당편집!$D$2:$N$2710,11,FALSE), 0) -> 0 | F5: =IFERROR(VLOOKUP(F$1&$A5&$B5,배당편집!$D$2:$N$2710,11,FALSE), 0) -> 0 | G5: =IFERROR(VLOOKUP(G$1&$A5&$B5,배당편집!$D$2:$N$2710,11,FALSE), 0) -> 0 | H5: =IFERROR(VLOOKUP(H$1&$A5&$B5,배당편집!$D$2:$N$2710,11,FALSE), 0) -> 0 | I5: =IFERROR(VLOOKUP(I$1&$A5&$B5,배당편집!$D$2:$N$2710,11,FALSE), 0) -> 0 | J5: =IFERROR(VLOOKUP(J$1&$A5&$B5,배당편집!$D$2:$N$2710,11,FALSE), 0) -> 0 | ... AF5: =IFERROR(VLOOKUP(AF$1&$A5&$B5,배당편집!$D$2:$N$2710,11,FALSE), 0) -> 0
A6: 2022 | B6: 5 | C6: =IFERROR(VLOOKUP(C$1&$A6&$B6,배당편집!$D$2:$N$2710,11,FALSE), 0) -> 0.4775 | D6: =IFERROR(VLOOKUP(D$1&$A6&$B6,배당편집!$D$2:$N$2710,11,FALSE), 0) -> 0 | E6: =IFERROR(VLOOKUP(E$1&$A6&$B6,배당편집!$D$2:$N$2710,11,FALSE), 0) -> 0 | F6: =IFERROR(VLOOKUP(F$1&$A6&$B6,배당편집!$D$2:$N$2710,11,FALSE), 0) -> 0 | G6: =IFERROR(VLOOKUP(G$1&$A6&$B6,배당편집!$D$2:$N$2710,11,FALSE), 0) -> 0.88 | H6: =IFERROR(VLOOKUP(H$1&$A6&$B6,배당편집!$D$2:$N$2710,11,FALSE), 0) -> 1.42 | I6: =IFERROR(VLOOKUP(I$1&$A6&$B6,배당편집!$D$2:$N$2710,11,FALSE), 0) -> 0.595 | J6: =IFERROR(VLOOKUP(J$1&$A6&$B6,배당편집!$D$2:$N$2710,11,FALSE), 0) -> 0 | ... AF6: =IFERROR(VLOOKUP(AF$1&$A6&$B6,배당편집!$D$2:$N$2710,11,FALSE), 0) -> 0.5
A7: 2022 | B7: 6 | C7: =IFERROR(VLOOKUP(C$1&$A7&$B7,배당편집!$D$2:$N$2710,11,FALSE), 0) -> 0 | D7: =IFERROR(VLOOKUP(D$1&$A7&$B7,배당편집!$D$2:$N$2710,11,FALSE), 0) -> 0.44 | E7: =IFERROR(VLOOKUP(E$1&$A7&$B7,배당편집!$D$2:$N$2710,11,FALSE), 0) -> 0.29 | F7: =IFERROR(VLOOKUP(F$1&$A7&$B7,배당편집!$D$2:$N$2710,11,FALSE), 0) -> 0.79 | G7: =IFERROR(VLOOKUP(G$1&$A7&$B7,배당편집!$D$2:$N$2710,11,FALSE), 0) -> 0 | H7: =IFERROR(VLOOKUP(H$1&$A7&$B7,배당편집!$D$2:$N$2710,11,FALSE), 0) -> 0 | I7: =IFERROR(VLOOKUP(I$1&$A7&$B7,배당편집!$D$2:$N$2710,11,FALSE), 0) -> 0 | J7: =IFERROR(VLOOKUP(J$1&$A7&$B7,배당편집!$D$2:$N$2710,11,FALSE), 0) -> 0.475 | ... AF7: =IFERROR(VLOOKUP(AF$1&$A7&$B7,배당편집!$D$2:$N$2710,11,FALSE), 0) -> 0
A8: 2022 | B8: 7 | C8: =IFERROR(VLOOKUP(C$1&$A8&$B8,배당편집!$D$2:$N$2710,11,FALSE), 0) -> 0 | D8: =IFERROR(VLOOKUP(D$1&$A8&$B8,배당편집!$D$2:$N$2710,11,FALSE), 0) -> 0 | E8: =IFERROR(VLOOKUP(E$1&$A8&$B8,배당편집!$D$2:$N$2710,11,FALSE), 0) -> 0 | F8: =IFERROR(VLOOKUP(F$1&$A8&$B8,배당편집!$D$2:$N$2710,11,FALSE), 0) -> 0 | G8: =IFERROR(VLOOKUP(G$1&$A8&$B8,배당편집!$D$2:$N$2710,11,FALSE), 0) -> 0 | H8: =IFERROR(VLOOKUP(H$1&$A8&$B8,배당편집!$D$2:$N$2710,11,FALSE), 0) -> 0 | I8: =IFERROR(VLOOKUP(I$1&$A8&$B8,배당편집!$D$2:$N$2710,11,FALSE), 0) -> 0 | J8: =IFERROR(VLOOKUP(J$1&$A8&$B8,배당편집!$D$2:$N$2710,11,FALSE), 0) -> 0 | ... AF8: =IFERROR(VLOOKUP(AF$1&$A8&$B8,배당편집!$D$2:$N$2710,11,FALSE), 0) -> 0
A9: 2022 | B9: 8 | C9: =IFERROR(VLOOKUP(C$1&$A9&$B9,배당편집!$D$2:$N$2710,11,FALSE), 0) -> 0.48 | D9: =IFERROR(VLOOKUP(D$1&$A9&$B9,배당편집!$D$2:$N$2710,11,FALSE), 0) -> 0 | E9: =IFERROR(VLOOKUP(E$1&$A9&$B9,배당편집!$D$2:$N$2710,11,FALSE), 0) -> 0 | F9: =IFERROR(VLOOKUP(F$1&$A9&$B9,배당편집!$D$2:$N$2710,11,FALSE), 0) -> 0 | G9: =IFERROR(VLOOKUP(G$1&$A9&$B9,배당편집!$D$2:$N$2710,11,FALSE), 0) -> 0.88 | H9: =IFERROR(VLOOKUP(H$1&$A9&$B9,배당편집!$D$2:$N$2710,11,FALSE), 0) -> 1.42 | I9: =IFERROR(VLOOKUP(I$1&$A9&$B9,배당편집!$D$2:$N$2710,11,FALSE), 0) -> 0.595 | J9: =IFERROR(VLOOKUP(J$1&$A9&$B9,배당편집!$D$2:$N$2710,11,FALSE), 0) -> 0 | ... AF9: =IFERROR(VLOOKUP(AF$1&$A9&$B9,배당편집!$D$2:$N$2710,11,FALSE), 0) -> 0.505
A10: 2022 | B10: 9 | C10: =IFERROR(VLOOKUP(C$1&$A10&$B10,배당편집!$D$2:$N$2710,11,FALSE), 0) -> 0 | D10: =IFERROR(VLOOKUP(D$1&$A10&$B10,배당편집!$D$2:$N$2710,11,FALSE), 0) -> 0.44 | E10: =IFERROR(VLOOKUP(E$1&$A10&$B10,배당편집!$D$2:$N$2710,11,FALSE), 0) -> 0.29 | F10: =IFERROR(VLOOKUP(F$1&$A10&$B10,배당편집!$D$2:$N$2710,11,FALSE), 0) -> 0.8 | G10: =IFERROR(VLOOKUP(G$1&$A10&$B10,배당편집!$D$2:$N$2710,11,FALSE), 0) -> 0 | H10: =IFERROR(VLOOKUP(H$1&$A10&$B10,배당편집!$D$2:$N$2710,11,FALSE), 0) -> 0 | I10: =IFERROR(VLOOKUP(I$1&$A10&$B10,배당편집!$D$2:$N$2710,11,FALSE), 0) -> 0 | J10: =IFERROR(VLOOKUP(J$1&$A10&$B10,배당편집!$D$2:$N$2710,11,FALSE), 0) -> 0.475 | ... AF10: =IFERROR(VLOOKUP(AF$1&$A10&$B10,배당편집!$D$2:$N$2710,11,FALSE), 0) -> 0
A11: 2022 | B11: 10 | C11: =IFERROR(VLOOKUP(C$1&$A11&$B11,배당편집!$D$2:$N$2710,11,FALSE), 0) -> 0 | D11: =IFERROR(VLOOKUP(D$1&$A11&$B11,배당편집!$D$2:$N$2710,11,FALSE), 0) -> 0 | E11: =IFERROR(VLOOKUP(E$1&$A11&$B11,배당편집!$D$2:$N$2710,11,FALSE), 0) -> 0 | F11: =IFERROR(VLOOKUP(F$1&$A11&$B11,배당편집!$D$2:$N$2710,11,FALSE), 0) -> 0 | G11: =IFERROR(VLOOKUP(G$1&$A11&$B11,배당편집!$D$2:$N$2710,11,FALSE), 0) -> 0 | H11: =IFERROR(VLOOKUP(H$1&$A11&$B11,배당편집!$D$2:$N$2710,11,FALSE), 0) -> 0 | I11: =IFERROR(VLOOKUP(I$1&$A11&$B11,배당편집!$D$2:$N$2710,11,FALSE), 0) -> 0 | J11: =IFERROR(VLOOKUP(J$1&$A11&$B11,배당편집!$D$2:$N$2710,11,FALSE), 0) -> 0 | ... AF11: =IFERROR(VLOOKUP(AF$1&$A11&$B11,배당편집!$D$2:$N$2710,11,FALSE), 0) -> 0
A12: 2022 | B12: 11 | C12: =IFERROR(VLOOKUP(C$1&$A12&$B12,배당편집!$D$2:$N$2710,11,FALSE), 0) -> 0.48 | D12: =IFERROR(VLOOKUP(D$1&$A12&$B12,배당편집!$D$2:$N$2710,11,FALSE), 0) -> 0 | E12: =IFERROR(VLOOKUP(E$1&$A12&$B12,배당편집!$D$2:$N$2710,11,FALSE), 0) -> 0 | F12: =IFERROR(VLOOKUP(F$1&$A12&$B12,배당편집!$D$2:$N$2710,11,FALSE), 0) -> 0.8 | G12: =IFERROR(VLOOKUP(G$1&$A12&$B12,배당편집!$D$2:$N$2710,11,FALSE), 0) -> 0 | H12: =IFERROR(VLOOKUP(H$1&$A12&$B12,배당편집!$D$2:$N$2710,11,FALSE), 0) -> 1.42 | I12: =IFERROR(VLOOKUP(I$1&$A12&$B12,배당편집!$D$2:$N$2710,11,FALSE), 0) -> 0.625 | J12: =IFERROR(VLOOKUP(J$1&$A12&$B12,배당편집!$D$2:$N$2710,11,FALSE), 0) -> 0 | ... AF12: =IFERROR(VLOOKUP(AF$1&$A12&$B12,배당편집!$D$2:$N$2710,11,FALSE), 0) -> 0
A13: 2022 | B13: 12 | C13: =IFERROR(VLOOKUP(C$1&$A13&$B13,배당편집!$D$2:$N$2710,11,FALSE), 0) -> 0 | D13: =IFERROR(VLOOKUP(D$1&$A13&$B13,배당편집!$D$2:$N$2710,11,FALSE), 0) -> 0 | E13: =IFERROR(VLOOKUP(E$1&$A13&$B13,배당편집!$D$2:$N$2710,11,FALSE), 0) -> 0 | F13: =IFERROR(VLOOKUP(F$1&$A13&$B13,배당편집!$D$2:$N$2710,11,FALSE), 0) -> 0 | G13: =IFERROR(VLOOKUP(G$1&$A13&$B13,배당편집!$D$2:$N$2710,11,FALSE), 0) -> 0 | H13: =IFERROR(VLOOKUP(H$1&$A13&$B13,배당편집!$D$2:$N$2710,11,FALSE), 0) -> 0 | I13: =IFERROR(VLOOKUP(I$1&$A13&$B13,배당편집!$D$2:$N$2710,11,FALSE), 0) -> 0 | J13: =IFERROR(VLOOKUP(J$1&$A13&$B13,배당편집!$D$2:$N$2710,11,FALSE), 0) -> 0 | ... AF13: =IFERROR(VLOOKUP(AF$1&$A13&$B13,배당편집!$D$2:$N$2710,11,FALSE), 0) -> 0
... A205: 2006 | B205: 12 | C205: =IFERROR(VLOOKUP(C$1&$A205&$B205,배당편집!$D$2:$N$2710,11,FALSE), 0) -> 0 | D205: =IFERROR(VLOOKUP(D$1&$A205&$B205,배당편집!$D$2:$N$2710,11,FALSE), 0) -> 0.17 | E205: =IFERROR(VLOOKUP(E$1&$A205&$B205,배당편집!$D$2:$N$2710,11,FALSE), 0) -> 0.05 | F205: =IFERROR(VLOOKUP(F$1&$A205&$B205,배당편집!$D$2:$N$2710,11,FALSE), 0) -> 0.3 | G205: =IFERROR(VLOOKUP(G$1&$A205&$B205,배당편집!$D$2:$N$2710,11,FALSE), 0) -> 0 | H205: =IFERROR(VLOOKUP(H$1&$A205&$B205,배당편집!$D$2:$N$2710,11,FALSE), 0) -> 0 | I205: =IFERROR(VLOOKUP(I$1&$A205&$B205,배당편집!$D$2:$N$2710,11,FALSE), 0) -> 0 | J205: =IFERROR(VLOOKUP(J$1&$A205&$B205,배당편집!$D$2:$N$2710,11,FALSE), 0) -> 0.3 | ... AF205: =IFERROR(VLOOKUP(AF$1&$A205&$B205,배당편집!$D$2:$N$2710,11,FALSE), 0) -> 0
